2025-05-07 21:26:23,657 [INFO] 2025-05-07 21:26:23 - tankahdelphia skipped: command not found for !random (account created: 2018-03-13)
2025-05-07 21:26:26,460 [INFO] 2025-05-07 21:26:26 - legendcrypt skipped: command not found for !random (account created: 2018-12-06)
2025-05-07 21:26:38,525 [INFO] 2025-05-07 21:26:38 - iamdar skipped: invalid characters in command for !! (account created: 2013-11-17)
2025-05-07 21:29:48,864 [INFO] 2025-05-07 21:29:48 - legendcrypt skipped: command not found for !b2y (account created: 2018-12-06)
2025-05-07 21:29:53,130 [INFO] 2025-05-07 21:29:53 - uppercumberlandgamers skipped: command not found for !al (account created: 2013-12-26)
2025-05-07 21:29:54,384 [INFO] 2025-05-07 21:29:54 - uppercumberlandgamers skipped: command not found for !la (account created: 2013-12-26)
2025-05-07 21:30:02,243 [INFO] 2025-05-07 21:30:02 - tankahdelphia skipped: command not found for !crap (account created: 2018-03-13)
2025-05-07 21:30:13,427 [INFO] 2025-05-07 21:30:13 - uppercumberlandgamers skipped: command not found for !meme (account created: 2013-12-26)
2025-05-07 21:30:22,926 [INFO] 2025-05-07 21:30:22 - uppercumberlandgamers skipped: command not found for !atl (account created: 2013-12-26)
2025-05-07 21:30:30,312 [INFO] 2025-05-07 21:30:30 - legendcrypt skipped: command not found for !deletesystem32 (account created: 2018-12-06)
2025-05-07 21:31:10,928 [INFO] 2025-05-07 21:31:10 - uppercumberlandgamers skipped: command not found for !sudo (account created: 2013-12-26)
2025-05-07 21:31:19,355 [INFO] 2025-05-07 21:31:19 - legendcrypt skipped: invalid characters in command for !fal<3 (account created: 2018-12-06)
2025-05-07 21:33:26,419 [ERROR] Task was destroyed but it is pending!
task: <Task pending name='Task-30' coro=<MeanGeneBot.watch_sfx_folder() running at E:\Dev\mean-gene-bot\bot\main.py:92> wait_for=<Future pending cb=[Task.task_wakeup()]>>
2025-05-07 21:37:17,871 [ERROR] Unhandled exception
Traceback (most recent call last):
  File "E:\Dev\mean-gene-bot\bot\venv\Lib\site-packages\twitchio\client.py", line 208, in wrapped
    await func(*args)
  File "E:\Dev\mean-gene-bot\bot\main.py", line 86, in event_command_error
    log_skip(reason, user, attempted, created)
    ~~~~~~~~^^^^^^^^^^^^^^^^^^^^^^^^^^^^^^^^^^
  File "E:\Dev\mean-gene-bot\bot\command_loader.py", line 16, in log_skip
    msg = f"\u26d4 {datetime.now().strftime('%Y-%m-%d %H:%M:%S')} - {user} skipped: {reason} for !{command}"
                ^^^^^^^^
NameError: name 'datetime' is not defined. Did you forget to import 'datetime'?
2025-05-07 21:37:34,293 [ERROR] Unhandled exception
Traceback (most recent call last):
  File "E:\Dev\mean-gene-bot\bot\venv\Lib\site-packages\twitchio\client.py", line 208, in wrapped
    await func(*args)
  File "E:\Dev\mean-gene-bot\bot\main.py", line 86, in event_command_error
    log_skip(reason, user, attempted, created)
    ~~~~~~~~^^^^^^^^^^^^^^^^^^^^^^^^^^^^^^^^^^
  File "E:\Dev\mean-gene-bot\bot\command_loader.py", line 16, in log_skip
    msg = f"\u26d4 {datetime.now().strftime('%Y-%m-%d %H:%M:%S')} - {user} skipped: {reason} for !{command}"
                ^^^^^^^^
NameError: name 'datetime' is not defined. Did you forget to import 'datetime'?
2025-05-07 21:38:18,158 [ERROR] Unhandled exception
Traceback (most recent call last):
  File "E:\Dev\mean-gene-bot\bot\venv\Lib\site-packages\twitchio\client.py", line 208, in wrapped
    await func(*args)
  File "E:\Dev\mean-gene-bot\bot\main.py", line 86, in event_command_error
    log_skip(reason, user, attempted, created)
    ~~~~~~~~^^^^^^^^^^^^^^^^^^^^^^^^^^^^^^^^^^
  File "E:\Dev\mean-gene-bot\bot\command_loader.py", line 16, in log_skip
    msg = f"\u26d4 {datetime.now().strftime('%Y-%m-%d %H:%M:%S')} - {user} skipped: {reason} for !{command}"
                ^^^^^^^^
NameError: name 'datetime' is not defined. Did you forget to import 'datetime'?
2025-05-07 21:39:32,072 [ERROR] Unhandled exception
Traceback (most recent call last):
  File "E:\Dev\mean-gene-bot\bot\venv\Lib\site-packages\twitchio\client.py", line 208, in wrapped
    await func(*args)
  File "E:\Dev\mean-gene-bot\bot\main.py", line 86, in event_command_error
    log_skip(reason, user, attempted, created)
    ~~~~~~~~^^^^^^^^^^^^^^^^^^^^^^^^^^^^^^^^^^
  File "E:\Dev\mean-gene-bot\bot\command_loader.py", line 16, in log_skip
    msg = f"\u26d4 {datetime.now().strftime('%Y-%m-%d %H:%M:%S')} - {user} skipped: {reason} for !{command}"
                ^^^^^^^^
NameError: name 'datetime' is not defined. Did you forget to import 'datetime'?
2025-05-07 21:40:17,967 [ERROR] Unhandled exception
Traceback (most recent call last):
  File "E:\Dev\mean-gene-bot\bot\venv\Lib\site-packages\twitchio\client.py", line 208, in wrapped
    await func(*args)
  File "E:\Dev\mean-gene-bot\bot\main.py", line 86, in event_command_error
    log_skip(reason, user, attempted, created)
    ~~~~~~~~^^^^^^^^^^^^^^^^^^^^^^^^^^^^^^^^^^
  File "E:\Dev\mean-gene-bot\bot\command_loader.py", line 16, in log_skip
    msg = f"\u26d4 {datetime.now().strftime('%Y-%m-%d %H:%M:%S')} - {user} skipped: {reason} for !{command}"
                ^^^^^^^^
NameError: name 'datetime' is not defined. Did you forget to import 'datetime'?
2025-05-07 21:40:19,006 [ERROR] Unhandled exception
Traceback (most recent call last):
  File "E:\Dev\mean-gene-bot\bot\venv\Lib\site-packages\twitchio\client.py", line 208, in wrapped
    await func(*args)
  File "E:\Dev\mean-gene-bot\bot\main.py", line 86, in event_command_error
    log_skip(reason, user, attempted, created)
    ~~~~~~~~^^^^^^^^^^^^^^^^^^^^^^^^^^^^^^^^^^
  File "E:\Dev\mean-gene-bot\bot\command_loader.py", line 16, in log_skip
    msg = f"\u26d4 {datetime.now().strftime('%Y-%m-%d %H:%M:%S')} - {user} skipped: {reason} for !{command}"
                ^^^^^^^^
NameError: name 'datetime' is not defined. Did you forget to import 'datetime'?
2025-05-07 21:42:19,785 [ERROR] Unhandled exception
Traceback (most recent call last):
  File "E:\Dev\mean-gene-bot\bot\venv\Lib\site-packages\twitchio\client.py", line 208, in wrapped
    await func(*args)
  File "E:\Dev\mean-gene-bot\bot\main.py", line 86, in event_command_error
    log_skip(reason, user, attempted, created)
    ~~~~~~~~^^^^^^^^^^^^^^^^^^^^^^^^^^^^^^^^^^
  File "E:\Dev\mean-gene-bot\bot\command_loader.py", line 16, in log_skip
    msg = f"\u26d4 {datetime.now().strftime('%Y-%m-%d %H:%M:%S')} - {user} skipped: {reason} for !{command}"
                ^^^^^^^^
NameError: name 'datetime' is not defined. Did you forget to import 'datetime'?
2025-05-07 21:44:53,257 [ERROR] Unhandled exception
Traceback (most recent call last):
  File "C:\Users\darji\AppData\Local\Programs\Python\Python313\Lib\site-packages\twitchio\client.py", line 208, in wrapped
    await func(*args)
  File "E:\Dev\mean-gene-bot\bot\main.py", line 86, in event_command_error
    log_skip(reason, user, attempted, created)
    ~~~~~~~~^^^^^^^^^^^^^^^^^^^^^^^^^^^^^^^^^^
  File "E:\Dev\mean-gene-bot\bot\command_loader.py", line 16, in log_skip
    msg = f"\u26d4 {datetime.now().strftime('%Y-%m-%d %H:%M:%S')} - {user} skipped: {reason} for !{command}"
                ^^^^^^^^
NameError: name 'datetime' is not defined. Did you forget to import 'datetime'?
2025-05-07 21:45:09,805 [ERROR] Unhandled exception
Traceback (most recent call last):
  File "C:\Users\darji\AppData\Local\Programs\Python\Python313\Lib\site-packages\twitchio\client.py", line 208, in wrapped
    await func(*args)
  File "E:\Dev\mean-gene-bot\bot\main.py", line 86, in event_command_error
    log_skip(reason, user, attempted, created)
    ~~~~~~~~^^^^^^^^^^^^^^^^^^^^^^^^^^^^^^^^^^
  File "E:\Dev\mean-gene-bot\bot\command_loader.py", line 16, in log_skip
    msg = f"\u26d4 {datetime.now().strftime('%Y-%m-%d %H:%M:%S')} - {user} skipped: {reason} for !{command}"
                ^^^^^^^^
NameError: name 'datetime' is not defined. Did you forget to import 'datetime'?
2025-05-07 21:46:58,702 [ERROR] Unhandled exception
Traceback (most recent call last):
  File "C:\Users\darji\AppData\Local\Programs\Python\Python313\Lib\site-packages\twitchio\client.py", line 208, in wrapped
    await func(*args)
  File "E:\Dev\mean-gene-bot\bot\main.py", line 86, in event_command_error
    log_skip(reason, user, attempted, created)
    ~~~~~~~~^^^^^^^^^^^^^^^^^^^^^^^^^^^^^^^^^^
  File "E:\Dev\mean-gene-bot\bot\command_loader.py", line 16, in log_skip
    msg = f"\u26d4 {datetime.now().strftime('%Y-%m-%d %H:%M:%S')} - {user} skipped: {reason} for !{command}"
                ^^^^^^^^
NameError: name 'datetime' is not defined. Did you forget to import 'datetime'?
2025-05-07 21:48:04,958 [ERROR] Unhandled exception
Traceback (most recent call last):
  File "C:\Users\darji\AppData\Local\Programs\Python\Python313\Lib\site-packages\twitchio\client.py", line 208, in wrapped
    await func(*args)
  File "E:\Dev\mean-gene-bot\bot\main.py", line 86, in event_command_error
    log_skip(reason, user, attempted, created)
    ~~~~~~~~^^^^^^^^^^^^^^^^^^^^^^^^^^^^^^^^^^
  File "E:\Dev\mean-gene-bot\bot\command_loader.py", line 16, in log_skip
    msg = f"\u26d4 {datetime.now().strftime('%Y-%m-%d %H:%M:%S')} - {user} skipped: {reason} for !{command}"
                ^^^^^^^^
NameError: name 'datetime' is not defined. Did you forget to import 'datetime'?
2025-05-07 21:49:17,807 [ERROR] Unhandled exception
Traceback (most recent call last):
  File "C:\Users\darji\AppData\Local\Programs\Python\Python313\Lib\site-packages\twitchio\client.py", line 208, in wrapped
    await func(*args)
  File "E:\Dev\mean-gene-bot\bot\main.py", line 86, in event_command_error
    log_skip(reason, user, attempted, created)
    ~~~~~~~~^^^^^^^^^^^^^^^^^^^^^^^^^^^^^^^^^^
  File "E:\Dev\mean-gene-bot\bot\command_loader.py", line 16, in log_skip
    msg = f"\u26d4 {datetime.now().strftime('%Y-%m-%d %H:%M:%S')} - {user} skipped: {reason} for !{command}"
                ^^^^^^^^
NameError: name 'datetime' is not defined. Did you forget to import 'datetime'?
2025-05-07 21:50:36,627 [ERROR] Unhandled exception
Traceback (most recent call last):
  File "C:\Users\darji\AppData\Local\Programs\Python\Python313\Lib\site-packages\twitchio\client.py", line 208, in wrapped
    await func(*args)
  File "E:\Dev\mean-gene-bot\bot\main.py", line 86, in event_command_error
    log_skip(reason, user, attempted, created)
    ~~~~~~~~^^^^^^^^^^^^^^^^^^^^^^^^^^^^^^^^^^
  File "E:\Dev\mean-gene-bot\bot\command_loader.py", line 16, in log_skip
    msg = f"\u26d4 {datetime.now().strftime('%Y-%m-%d %H:%M:%S')} - {user} skipped: {reason} for !{command}"
                ^^^^^^^^
NameError: name 'datetime' is not defined. Did you forget to import 'datetime'?
2025-05-07 21:53:50,087 [ERROR] Task was destroyed but it is pending!
task: <Task pending name='Task-29' coro=<MeanGeneBot.watch_sfx_folder() running at E:\Dev\mean-gene-bot\bot\main.py:92> wait_for=<Future pending cb=[Task.task_wakeup()]>>
2025-05-08 01:55:20,473 [ERROR] Task exception was never retrieved
future: <Task finished name='Task-32' coro=<MeanGeneBot.watch_sfx_folder() done, defined at E:\Dev\mean-gene-bot\bot\main.py:88> exception=TwitchCommandError('Failed to load command <sfxcount>, a command with that name already exists.')>
Traceback (most recent call last):
  File "E:\Dev\mean-gene-bot\bot\main.py", line 96, in watch_sfx_folder
  File "E:\Dev\mean-gene-bot\bot\command_loader.py", line 93, in load_sfx_commands
  File "C:\Users\darji\AppData\Local\Programs\Python\Python313\Lib\site-packages\twitchio\ext\commands\bot.py", line 197, in add_command
twitchio.ext.commands.errors.TwitchCommandError: Failed to load command <sfxcount>, a command with that name already exists.
2025-05-08 01:59:45,967 [ERROR] Task exception was never retrieved
future: <Task finished name='Task-29' coro=<MeanGeneBot.watch_sfx_folder() done, defined at E:\Dev\mean-gene-bot\bot\main.py:88> exception=TwitchCommandError('Failed to load command <sfxcount>, a command with that name already exists.')>
Traceback (most recent call last):
  File "E:\Dev\mean-gene-bot\bot\main.py", line 96, in watch_sfx_folder
  File "E:\Dev\mean-gene-bot\bot\command_loader.py", line 89, in load_sfx_commands
  File "C:\Users\darji\AppData\Local\Programs\Python\Python313\Lib\site-packages\twitchio\ext\commands\bot.py", line 197, in add_command
twitchio.ext.commands.errors.TwitchCommandError: Failed to load command <sfxcount>, a command with that name already exists.
2025-05-08 02:04:05,145 [ERROR] Task exception was never retrieved
future: <Task finished name='Task-31' coro=<MeanGeneBot.watch_sfx_folder() done, defined at E:\Dev\mean-gene-bot\bot\main.py:88> exception=TwitchCommandError('Failed to load command <sfxcount>, a command with that name already exists.')>
Traceback (most recent call last):
  File "E:\Dev\mean-gene-bot\bot\main.py", line 96, in watch_sfx_folder
  File "E:\Dev\mean-gene-bot\bot\command_loader.py", line 89, in load_sfx_commands
  File "C:\Users\darji\AppData\Local\Programs\Python\Python313\Lib\site-packages\twitchio\ext\commands\bot.py", line 197, in add_command
twitchio.ext.commands.errors.TwitchCommandError: Failed to load command <sfxcount>, a command with that name already exists.
2025-05-08 02:06:27,185 [ERROR] Task exception was never retrieved
future: <Task finished name='Task-29' coro=<MeanGeneBot.watch_sfx_folder() done, defined at E:\Dev\mean-gene-bot\bot\main.py:88> exception=AttributeError("module 'twitchio.ext.commands.errors' has no attribute 'CommandAlreadyExists'")>
Traceback (most recent call last):
  File "E:\Dev\mean-gene-bot\bot\command_loader.py", line 58, in load_sfx_commands
  File "C:\Users\darji\AppData\Local\Programs\Python\Python313\Lib\site-packages\twitchio\ext\commands\bot.py", line 197, in add_command
twitchio.ext.commands.errors.TwitchCommandError: Failed to load command <14>, a command with that name already exists.

During handling of the above exception, another exception occurred:

Traceback (most recent call last):
  File "E:\Dev\mean-gene-bot\bot\main.py", line 96, in watch_sfx_folder
  File "E:\Dev\mean-gene-bot\bot\command_loader.py", line 62, in load_sfx_commands
AttributeError: module 'twitchio.ext.commands.errors' has no attribute 'CommandAlreadyExists'
2025-05-08 02:09:16,254 [ERROR] Task exception was never retrieved
future: <Task finished name='Task-29' coro=<MeanGeneBot.watch_sfx_folder() done, defined at E:\Dev\mean-gene-bot\bot\main.py:88> exception=AttributeError("module 'twitchio.ext.commands.errors' has no attribute 'CommandAlreadyExists'")>
Traceback (most recent call last):
  File "E:\Dev\mean-gene-bot\bot\command_loader.py", line 59, in load_sfx_commands
  File "C:\Users\darji\AppData\Local\Programs\Python\Python313\Lib\site-packages\twitchio\ext\commands\bot.py", line 197, in add_command
twitchio.ext.commands.errors.TwitchCommandError: Failed to load command <14>, a command with that name already exists.

During handling of the above exception, another exception occurred:

Traceback (most recent call last):
  File "E:\Dev\mean-gene-bot\bot\main.py", line 96, in watch_sfx_folder
  File "E:\Dev\mean-gene-bot\bot\command_loader.py", line 63, in load_sfx_commands
AttributeError: module 'twitchio.ext.commands.errors' has no attribute 'CommandAlreadyExists'
2025-05-08 02:14:19,371 [ERROR] Task was destroyed but it is pending!
task: <Task pending name='Task-29' coro=<MeanGeneBot.watch_sfx_folder() running at E:\Dev\mean-gene-bot\bot\main.py:92> wait_for=<Future pending cb=[Task.task_wakeup()]>>
2025-05-08 02:17:23,444 [ERROR] Task was destroyed but it is pending!
task: <Task pending name='Task-30' coro=<MeanGeneBot.watch_sfx_folder() running at E:\Dev\mean-gene-bot\bot\main.py:92> wait_for=<Future pending cb=[Task.task_wakeup()]>>
2025-05-08 02:19:34,228 [ERROR] Task was destroyed but it is pending!
task: <Task pending name='Task-29' coro=<MeanGeneBot.watch_sfx_folder() running at E:\Dev\mean-gene-bot\bot\main.py:92> wait_for=<Future pending cb=[Task.task_wakeup()]>>
2025-05-08 02:22:48,021 [ERROR] Task exception was never retrieved
future: <Task finished name='Task-29' coro=<MeanGeneBot.watch_sfx_folder() done, defined at E:\Dev\mean-gene-bot\bot\main.py:88> exception=AttributeError("module 'twitchio.ext.commands.errors' has no attribute 'CommandAlreadyExists'")>
Traceback (most recent call last):
  File "E:\Dev\mean-gene-bot\bot\command_loader.py", line 60, in load_sfx_commands
  File "C:\Users\darji\AppData\Local\Programs\Python\Python313\Lib\site-packages\twitchio\ext\commands\bot.py", line 197, in add_command
twitchio.ext.commands.errors.TwitchCommandError: Failed to load command <!>, a command with that name already exists.

During handling of the above exception, another exception occurred:

Traceback (most recent call last):
  File "E:\Dev\mean-gene-bot\bot\main.py", line 96, in watch_sfx_folder
  File "E:\Dev\mean-gene-bot\bot\command_loader.py", line 63, in load_sfx_commands
AttributeError: module 'twitchio.ext.commands.errors' has no attribute 'CommandAlreadyExists'
2025-05-08 02:24:00,614 [ERROR] Task exception was never retrieved
future: <Task finished name='Task-29' coro=<MeanGeneBot.watch_sfx_folder() done, defined at E:\Dev\mean-gene-bot\bot\main.py:88> exception=AttributeError("module 'twitchio.ext.commands.errors' has no attribute 'CommandAlreadyExists'")>
Traceback (most recent call last):
  File "E:\Dev\mean-gene-bot\bot\command_loader.py", line 60, in load_sfx_commands
  File "C:\Users\darji\AppData\Local\Programs\Python\Python313\Lib\site-packages\twitchio\ext\commands\bot.py", line 197, in add_command
twitchio.ext.commands.errors.TwitchCommandError: Failed to load command <!>, a command with that name already exists.

During handling of the above exception, another exception occurred:

Traceback (most recent call last):
  File "E:\Dev\mean-gene-bot\bot\main.py", line 96, in watch_sfx_folder
  File "E:\Dev\mean-gene-bot\bot\command_loader.py", line 63, in load_sfx_commands
AttributeError: module 'twitchio.ext.commands.errors' has no attribute 'CommandAlreadyExists'
2025-05-08 02:25:15,995 [ERROR] Task exception was never retrieved
future: <Task finished name='Task-29' coro=<MeanGeneBot.watch_sfx_folder() done, defined at E:\Dev\mean-gene-bot\bot\main.py:88> exception=AttributeError("module 'twitchio.ext.commands.errors' has no attribute 'CommandAlreadyExists'")>
Traceback (most recent call last):
  File "E:\Dev\mean-gene-bot\bot\command_loader.py", line 60, in load_sfx_commands
  File "C:\Users\darji\AppData\Local\Programs\Python\Python313\Lib\site-packages\twitchio\ext\commands\bot.py", line 197, in add_command
twitchio.ext.commands.errors.TwitchCommandError: Failed to load command <!>, a command with that name already exists.

During handling of the above exception, another exception occurred:

Traceback (most recent call last):
  File "E:\Dev\mean-gene-bot\bot\main.py", line 96, in watch_sfx_folder
  File "E:\Dev\mean-gene-bot\bot\command_loader.py", line 63, in load_sfx_commands
AttributeError: module 'twitchio.ext.commands.errors' has no attribute 'CommandAlreadyExists'
2025-05-08 02:26:24,350 [ERROR] Task exception was never retrieved
future: <Task finished name='Task-29' coro=<MeanGeneBot.watch_sfx_folder() done, defined at E:\Dev\mean-gene-bot\bot\main.py:88> exception=AttributeError("module 'twitchio.ext.commands.errors' has no attribute 'CommandAlreadyExists'")>
Traceback (most recent call last):
  File "E:\Dev\mean-gene-bot\bot\command_loader.py", line 60, in load_sfx_commands
  File "C:\Users\darji\AppData\Local\Programs\Python\Python313\Lib\site-packages\twitchio\ext\commands\bot.py", line 197, in add_command
twitchio.ext.commands.errors.TwitchCommandError: Failed to load command <!>, a command with that name already exists.

During handling of the above exception, another exception occurred:

Traceback (most recent call last):
  File "E:\Dev\mean-gene-bot\bot\main.py", line 96, in watch_sfx_folder
  File "E:\Dev\mean-gene-bot\bot\command_loader.py", line 63, in load_sfx_commands
AttributeError: module 'twitchio.ext.commands.errors' has no attribute 'CommandAlreadyExists'
2025-05-08 02:27:11,624 [ERROR] Task exception was never retrieved
future: <Task finished name='Task-29' coro=<MeanGeneBot.watch_sfx_folder() done, defined at E:\Dev\mean-gene-bot\bot\main.py:88> exception=AttributeError("module 'twitchio.ext.commands.errors' has no attribute 'CommandAlreadyExists'")>
Traceback (most recent call last):
  File "E:\Dev\mean-gene-bot\bot\command_loader.py", line 60, in load_sfx_commands
  File "C:\Users\darji\AppData\Local\Programs\Python\Python313\Lib\site-packages\twitchio\ext\commands\bot.py", line 197, in add_command
twitchio.ext.commands.errors.TwitchCommandError: Failed to load command <!>, a command with that name already exists.

During handling of the above exception, another exception occurred:

Traceback (most recent call last):
  File "E:\Dev\mean-gene-bot\bot\main.py", line 96, in watch_sfx_folder
  File "E:\Dev\mean-gene-bot\bot\command_loader.py", line 63, in load_sfx_commands
AttributeError: module 'twitchio.ext.commands.errors' has no attribute 'CommandAlreadyExists'
2025-05-08 02:28:37,921 [ERROR] Task exception was never retrieved
future: <Task finished name='Task-30' coro=<MeanGeneBot.watch_sfx_folder() done, defined at E:\Dev\mean-gene-bot\bot\main.py:88> exception=AttributeError("module 'twitchio.ext.commands.errors' has no attribute 'CommandAlreadyExists'")>
Traceback (most recent call last):
  File "E:\Dev\mean-gene-bot\bot\command_loader.py", line 60, in load_sfx_commands
  File "C:\Users\darji\AppData\Local\Programs\Python\Python313\Lib\site-packages\twitchio\ext\commands\bot.py", line 197, in add_command
twitchio.ext.commands.errors.TwitchCommandError: Failed to load command <!>, a command with that name already exists.

During handling of the above exception, another exception occurred:

Traceback (most recent call last):
  File "E:\Dev\mean-gene-bot\bot\main.py", line 96, in watch_sfx_folder
  File "E:\Dev\mean-gene-bot\bot\command_loader.py", line 63, in load_sfx_commands
AttributeError: module 'twitchio.ext.commands.errors' has no attribute 'CommandAlreadyExists'
2025-05-08 11:48:06,887 [ERROR] Task exception was never retrieved
future: <Task finished name='Task-29' coro=<MeanGeneBot.watch_sfx_folder() done, defined at E:\Dev\mean-gene-bot\bot\main.py:88> exception=AttributeError("module 'twitchio.ext.commands.errors' has no attribute 'CommandAlreadyExists'")>
Traceback (most recent call last):
  File "E:\Dev\mean-gene-bot\bot\command_loader.py", line 60, in load_sfx_commands
  File "C:\Users\darji\AppData\Local\Programs\Python\Python313\Lib\site-packages\twitchio\ext\commands\bot.py", line 197, in add_command
twitchio.ext.commands.errors.TwitchCommandError: Failed to load command <!>, a command with that name already exists.

During handling of the above exception, another exception occurred:

Traceback (most recent call last):
  File "E:\Dev\mean-gene-bot\bot\main.py", line 96, in watch_sfx_folder
  File "E:\Dev\mean-gene-bot\bot\command_loader.py", line 63, in load_sfx_commands
AttributeError: module 'twitchio.ext.commands.errors' has no attribute 'CommandAlreadyExists'
2025-05-08 11:53:54,663 [ERROR] Task exception was never retrieved
future: <Task finished name='Task-29' coro=<MeanGeneBot.watch_sfx_folder() done, defined at E:\Dev\mean-gene-bot\bot\main.py:88> exception=AttributeError("module 'twitchio.ext.commands.errors' has no attribute 'CommandAlreadyExists'")>
Traceback (most recent call last):
  File "E:\Dev\mean-gene-bot\bot\command_loader.py", line 60, in load_sfx_commands
  File "C:\Users\darji\AppData\Local\Programs\Python\Python313\Lib\site-packages\twitchio\ext\commands\bot.py", line 197, in add_command
twitchio.ext.commands.errors.TwitchCommandError: Failed to load command <!>, a command with that name already exists.

During handling of the above exception, another exception occurred:

Traceback (most recent call last):
  File "E:\Dev\mean-gene-bot\bot\main.py", line 96, in watch_sfx_folder
  File "E:\Dev\mean-gene-bot\bot\command_loader.py", line 63, in load_sfx_commands
AttributeError: module 'twitchio.ext.commands.errors' has no attribute 'CommandAlreadyExists'
2025-05-08 11:55:23,826 [ERROR] Task exception was never retrieved
future: <Task finished name='Task-30' coro=<MeanGeneBot.watch_sfx_folder() done, defined at E:\Dev\mean-gene-bot\bot\main.py:88> exception=AttributeError("module 'twitchio.ext.commands.errors' has no attribute 'CommandAlreadyExists'")>
Traceback (most recent call last):
  File "E:\Dev\mean-gene-bot\bot\command_loader.py", line 60, in load_sfx_commands
  File "C:\Users\darji\AppData\Local\Programs\Python\Python313\Lib\site-packages\twitchio\ext\commands\bot.py", line 197, in add_command
twitchio.ext.commands.errors.TwitchCommandError: Failed to load command <!>, a command with that name already exists.

During handling of the above exception, another exception occurred:

Traceback (most recent call last):
  File "E:\Dev\mean-gene-bot\bot\main.py", line 96, in watch_sfx_folder
  File "E:\Dev\mean-gene-bot\bot\command_loader.py", line 63, in load_sfx_commands
AttributeError: module 'twitchio.ext.commands.errors' has no attribute 'CommandAlreadyExists'
2025-05-08 11:58:02,877 [ERROR] Task was destroyed but it is pending!
task: <Task pending name='Task-29' coro=<MeanGeneBot.watch_sfx_folder() running at E:\Dev\mean-gene-bot\bot\main.py:92> wait_for=<Future pending cb=[Task.task_wakeup()]>>
2025-05-08 12:10:26,706 [ERROR] Task exception was never retrieved
future: <Task finished name='Task-29' coro=<MeanGeneBot.watch_sfx_folder() done, defined at E:\Dev\mean-gene-bot\bot\main.py:88> exception=AttributeError("module 'twitchio.ext.commands.errors' has no attribute 'CommandAlreadyExists'")>
Traceback (most recent call last):
  File "E:\Dev\mean-gene-bot\bot\command_loader.py", line 60, in load_sfx_commands
  File "C:\Users\darji\AppData\Local\Programs\Python\Python313\Lib\site-packages\twitchio\ext\commands\bot.py", line 197, in add_command
twitchio.ext.commands.errors.TwitchCommandError: Failed to load command <!>, a command with that name already exists.

During handling of the above exception, another exception occurred:

Traceback (most recent call last):
  File "E:\Dev\mean-gene-bot\bot\main.py", line 96, in watch_sfx_folder
  File "E:\Dev\mean-gene-bot\bot\command_loader.py", line 63, in load_sfx_commands
AttributeError: module 'twitchio.ext.commands.errors' has no attribute 'CommandAlreadyExists'
2025-05-08 12:14:48,941 [ERROR] Task exception was never retrieved
future: <Task finished name='Task-29' coro=<MeanGeneBot.watch_sfx_folder() done, defined at E:\Dev\mean-gene-bot\bot\main.py:88> exception=AttributeError("module 'twitchio.ext.commands.errors' has no attribute 'CommandAlreadyExists'")>
Traceback (most recent call last):
  File "E:\Dev\mean-gene-bot\bot\command_loader.py", line 60, in load_sfx_commands
  File "C:\Users\darji\AppData\Local\Programs\Python\Python313\Lib\site-packages\twitchio\ext\commands\bot.py", line 197, in add_command
twitchio.ext.commands.errors.TwitchCommandError: Failed to load command <!>, a command with that name already exists.

During handling of the above exception, another exception occurred:

Traceback (most recent call last):
  File "E:\Dev\mean-gene-bot\bot\main.py", line 96, in watch_sfx_folder
  File "E:\Dev\mean-gene-bot\bot\command_loader.py", line 63, in load_sfx_commands
AttributeError: module 'twitchio.ext.commands.errors' has no attribute 'CommandAlreadyExists'
2025-05-08 12:18:49,627 [ERROR] Task was destroyed but it is pending!
task: <Task pending name='Task-29' coro=<MeanGeneBot.watch_sfx_folder() running at E:\Dev\mean-gene-bot\bot\main.py:92> wait_for=<Future pending cb=[Task.task_wakeup()]>>
2025-05-08 12:27:56,556 [ERROR] Task exception was never retrieved
future: <Task finished name='Task-29' coro=<MeanGeneBot.watch_sfx_folder() done, defined at E:\Dev\mean-gene-bot\bot\main.py:89> exception=AttributeError("module 'twitchio.ext.commands.errors' has no attribute 'CommandAlreadyExists'")>
Traceback (most recent call last):
  File "E:\Dev\mean-gene-bot\bot\command_loader.py", line 60, in load_sfx_commands
  File "C:\Users\darji\AppData\Local\Programs\Python\Python313\Lib\site-packages\twitchio\ext\commands\bot.py", line 197, in add_command
twitchio.ext.commands.errors.TwitchCommandError: Failed to load command <!>, a command with that name already exists.

During handling of the above exception, another exception occurred:

Traceback (most recent call last):
  File "E:\Dev\mean-gene-bot\bot\main.py", line 99, in watch_sfx_folder
  File "E:\Dev\mean-gene-bot\bot\command_loader.py", line 63, in load_sfx_commands
AttributeError: module 'twitchio.ext.commands.errors' has no attribute 'CommandAlreadyExists'
2025-05-08 12:34:04,458 [ERROR] Task exception was never retrieved
future: <Task finished name='Task-29' coro=<MeanGeneBot.watch_sfx_folder() done, defined at E:\Dev\mean-gene-bot\bot\main.py:89> exception=AttributeError("module 'twitchio.ext.commands.errors' has no attribute 'CommandAlreadyExists'")>
Traceback (most recent call last):
  File "E:\Dev\mean-gene-bot\bot\command_loader.py", line 60, in load_sfx_commands
  File "C:\Users\darji\AppData\Local\Programs\Python\Python313\Lib\site-packages\twitchio\ext\commands\bot.py", line 197, in add_command
twitchio.ext.commands.errors.TwitchCommandError: Failed to load command <!>, a command with that name already exists.

During handling of the above exception, another exception occurred:

Traceback (most recent call last):
  File "E:\Dev\mean-gene-bot\bot\main.py", line 99, in watch_sfx_folder
  File "E:\Dev\mean-gene-bot\bot\command_loader.py", line 64, in load_sfx_commands
AttributeError: module 'twitchio.ext.commands.errors' has no attribute 'CommandAlreadyExists'
2025-05-08 12:36:35,197 [ERROR] Task was destroyed but it is pending!
task: <Task pending name='Task-29' coro=<MeanGeneBot.watch_sfx_folder() running at E:\Dev\mean-gene-bot\bot\main.py:94> wait_for=<Future pending cb=[Task.task_wakeup()]>>
2025-05-08 12:37:10,669 [ERROR] Task was destroyed but it is pending!
task: <Task pending name='Task-29' coro=<MeanGeneBot.watch_sfx_folder() running at E:\Dev\mean-gene-bot\bot\main.py:94> wait_for=<Future pending cb=[Task.task_wakeup()]>>
2025-05-08 12:44:35,506 [ERROR] Task was destroyed but it is pending!
task: <Task pending name='Task-29' coro=<MeanGeneBot.watch_sfx_folder() running at E:\Dev\mean-gene-bot\bot\main.py:94> wait_for=<Future pending cb=[Task.task_wakeup()]>>
2025-05-08 12:49:11,688 [ERROR] Task was destroyed but it is pending!
task: <Task pending name='Task-29' coro=<MeanGeneBot.watch_sfx_folder() running at E:\Dev\mean-gene-bot\bot\main.py:94> wait_for=<Future pending cb=[Task.task_wakeup()]>>
2025-05-08 12:51:51,541 [ERROR] Task was destroyed but it is pending!
task: <Task pending name='Task-29' coro=<MeanGeneBot.watch_sfx_folder() running at E:\Dev\mean-gene-bot\bot\main.py:94> wait_for=<Future pending cb=[Task.task_wakeup()]>>
2025-05-08 14:04:21,832 [ERROR] Task was destroyed but it is pending!
task: <Task pending name='Task-30' coro=<MeanGeneBot.watch_sfx_folder() running at E:\Dev\mean-gene-bot\bot\main.py:94> wait_for=<Future pending cb=[Task.task_wakeup()]>>
2025-05-09 01:26:28,340 [ERROR] Task was destroyed but it is pending!
task: <Task pending name='Task-29' coro=<MeanGeneBot.watch_sfx_folder() running at E:\Dev\mean-gene-bot\bot\main.py:94> wait_for=<Future pending cb=[Task.task_wakeup()]>>
